Workbook

Sheet Cover Page
B2: Tesco plc - Discounted Cash Flow Valuation
B7: Prepared by Usman Khalid
B11: Purpose : Independent valuation model developed to strengthen financial modelling and valuation skills using publicly available financial information.
B17: For any questions please email usman123_@hotmail.co.uk
B19: Valuation Summary:
B20: Enterprise Value: | D20: £47,432M
B21: Equity Value: | D21: £35,017M
B22: Implied Share Price: | D22: 5.2
B23: WACC: | D23: 0.066
B24: Terminal Growth Rate: | D24: 0.02

Sheet Free Cash Flow
A1: Unlevered Free Cash Flow
B2: Year | C2: 2023 | D2: 2024 | E2: 2025 | F2: 2026E | G2: 2027E | H2: 2028E | I2: 2029E | J2: 2030E
B3: Revenue | C3: 65762 | D3: 68187 | E3: 69916 | F3: =E3*(1+F21) -> 71663.9 | G3: =F3*(1+G21) -> 73312.17 | H3: =G3*(1+H21) -> 74851.725 | I3: =H3*(1+I21) -> 76348.76 | J3: =I3*(1+J21) -> 77875.735
B4: COGS | C4: -62034 | D4: -62836 | E4: -64205 | F4: =F3*F23 -> -66483.833 | G4: =G3*G23 -> -68012.961 | H4: =H3*H23 -> -69441.234 | I4: =I3*I23 -> -70830.058 | J4: =J3*J23 -> -72246.659
B5: Gross Profit | C5: =SUM(C3:C4) -> 3728 | D5: =SUM(D3:D4) -> 5351 | E5: =SUM(E3:E4) -> 5711 | F5: =SUM(F3:F4) -> 5180.0668 | G5: =SUM(G3:G4) -> 5299.2083 | H5: =SUM(H3:H4) -> 5410.4917 | I5: =SUM(I3:I4) -> 5518.7016 | J5: =SUM(J3:J4) -> 5629.0756
B6: Operating Expenses
B7: Administrative Expenses | C7: ='Income Statements'!C12 -> -2136 | D7: ='Income Statements'!D12 -> -2028 | E7: ='Income Statements'!E12 -> -2340 | F7: =F3*F24 -> -2285.8691 | G7: =G3*G24 -> -2338.4441 | H7: =H3*H24 -> -2387.5514 | I7: =I3*I24 -> -2435.3024 | J7: =J3*J24 -> -2484.0085
B8: Operating Profit (EBIT) | C8: =SUM(C5:C7) -> 1592 | D8: =SUM(D5:D7) -> 3323 | E8: =SUM(E5:E7) -> 3371 | F8: =SUM(F5:F7) -> 2894.1977 | G8: =SUM(G5:G7) -> 2960.7643 | H8: =SUM(H5:H7) -> 3022.9403 | I8: =SUM(I5:I7) -> 3083.3991 | J8: =SUM(J5:J7) -> 3145.0671
B9: * Tax Rate | C9: =(0.269)*C8 -> 428.248 | D9: =(0.269)*D8 -> 893.887 | E9: =(0.269)*E8 -> 906.799 | F9: =(0.269)*F8 -> 778.53919 | G9: =(0.269)*G8 -> 796.44559 | H9: =(0.269)*H8 -> 813.17095 | I9: =(0.269)*I8 -> 829.43436 | J9: =(0.269)*J8 -> 846.02305
B10: NOPAT (Net Operating Profit After Taxes) | C10: =C8-C9 -> 1163.752 | D10: =D8-D9 -> 2429.113 | E10: =E8-E9 -> 2464.201 | F10: =F8-F9 -> 2115.6585 | G10: =G8-G9 -> 2164.3187 | H10: =H8-H9 -> 2209.7694 | I10: =I8-I9 -> 2253.9648 | J10: =J8-J9 -> 2299.0441
B11: (+) Depreciation & Amortization | C11: ='Cash Flow Statement'!C5 -> 1700 | D11: ='Cash Flow Statement'!D5 -> 1723 | E11: ='Cash Flow Statement'!E5 -> 1775 | F11: ='Capital Expenditures'!F4 -> 1754.4093 | G11: ='Capital Expenditures'!G4 -> 1761.4651 | H11: ='Capital Expenditures'!H4 -> 1768.5492 | I11: ='Capital Expenditures'!I4 -> 1775.6618 | J11: ='Capital Expenditures'!J4 -> 1782.8031
B12: (-) Capital Expenditures | C12: ='Capital Expenditures'!C5 -> 1502 | D12: ='Capital Expenditures'!D5 -> 2082 | E12: ='Capital Expenditures'!E5 -> 1816 | F12: ='Capital Expenditures'!F5 -> 1823.8324 | G12: ='Capital Expenditures'!G5 -> 1831.1674 | H12: ='Capital Expenditures'!H5 -> 1838.5318 | I12: ='Capital Expenditures'!I5 -> 1845.9259 | J12: ='Capital Expenditures'!J5 -> 1853.3497
B13: (-) Change in NWC | C13: =C14-('Net Working Capital'!C5+'Net Working Capital'!C9) -> -497 | D13: =D14-('Net Working Capital'!D5+'Net Working Capital'!D9) -> -227 | E13: =E14-('Net Working Capital'!E5+'Net Working Capital'!E9) -> -100 | F13: =F14-('Net Working Capital'!F5+'Net Working Capital'!F9) -> -216.20323 | G13: =G14-('Net Working Capital'!G5+'Net Working Capital'!G9) -> -158.75067 | H13: =H14-('Net Working Capital'!H5+'Net Working Capital'!H9) -> -148.28003 | I13: =I14-('Net Working Capital'!I5+'Net Working Capital'!I9) -> -144.18468 | J13: =J14-('Net Working Capital'!J5+'Net Working Capital'!J9) -> -147.06837
B14: NWC | C14: =SUM(C15:C16) -> -6359 | D14: =SUM(D15:D16) -> -6586 | E14: =SUM(E15:E16) -> -6686 | F14: =SUM(F15:F16) -> -6902.2032 | G14: =SUM(G15:G16) -> -7060.9539 | H14: =SUM(H15:H16) -> -7209.2339 | I14: =SUM(I15:I16) -> -7353.4186 | J14: =SUM(J15:J16) -> -7500.487
B15: Current Assets | C15: {='Net Working Capital'!D5:F5} -> 3825 | D15: 3984 | E15: 3978 | F15: ='Net Working Capital'!G5 -> 4145.1052 | G15: ='Net Working Capital'!H5 -> 4240.4427 | H15: ='Net Working Capital'!I5 -> 4329.492 | I15: ='Net Working Capital'!J5 -> 4416.0818 | J15: ='Net Working Capital'!K5 -> 4504.4034
B16: Current Liabilitites | C16: {='Net Working Capital'!D9:F9} -> -10184 | D16: -10570 | E16: -10664 | F16: ='Net Working Capital'!G9 -> -11047.308 | G16: ='Net Working Capital'!H9 -> -11301.397 | H16: ='Net Working Capital'!I9 -> -11538.726 | I16: ='Net Working Capital'!J9 -> -11769.5 | J16: ='Net Working Capital'!K9 -> -12004.89
B17: Unlevered Free Cash Flow | C17: =C10+C11-C12-C13 -> 1858.752 | D17: =D10+D11-D12-D13 -> 2297.113 | E17: =E10+E11-E12-E13 -> 2523.201 | F17: =F10+F11-F12-F13 -> 2262.4386 | G17: =G10+G11-G12-G13 -> 2253.367 | H17: =H10+H11-H12-H13 -> 2288.0668 | I17: =I10+I11-I12-I13 -> 2327.8853 | J17: =J10+J11-J12-J13 -> 2375.5657
A19: Assumptions
B20: Year | C20: 2023 | D20: 2024 | E20: 2025 | F20: 2026E | G20: 2027E | H20: 2028E | I20: 2029E | J20: 2030E
B21: Revenue growth | D21: =(D3/C3)-1 -> 0.036875399 | E21: =(E3/D3)-1 -> 0.02535674 | F21: 0.025 | G21: 0.023 | H21: 0.021 | I21: 0.02 | J21: 0.02
B23: COGS % of Revenue | C23: =C4/C3 -> -0.94331073 | D23: =D4/D3 -> -0.92152463 | E23: =E4/E3 -> -0.91831627 | F23: =AVERAGE(C23:E23) -> -0.92771721 | G23: =F23 -> -0.92771721 | H23: =F23 -> -0.92771721 | I23: =F23 -> -0.92771721 | J23: =F23 -> -0.92771721
B24: Administrative % of Revenue | C24: =C7/C3 -> -0.032480764 | D24: =D7/D3 -> -0.02974174 | E24: =E7/E3 -> -0.033468734 | F24: =AVERAGE(C24:E24) -> -0.031897079 | G24: =F24 -> -0.031897079 | H24: =F24 -> -0.031897079 | I24: =F24 -> -0.031897079 | J24: =F24 -> -0.031897079

Sheet DCF
A1: Unlevered Free Cash Flow
B2: Year | C2: 2023 | D2: 2024 | E2: 2025 | F2: 2026E | G2: 2027E | H2: 2028E | I2: 2029E | J2: 2030E
B3: Unlevered Free Cash Flow | C3: ='Free Cash Flow'!C17 -> 1858.752 | D3: ='Free Cash Flow'!D17 -> 2297.113 | E3: ='Free Cash Flow'!E17 -> 2523.201 | F3: ='Free Cash Flow'!F17 -> 2262.4386 | G3: ='Free Cash Flow'!G17 -> 2253.367 | H3: ='Free Cash Flow'!H17 -> 2288.0668 | I3: ='Free Cash Flow'!I17 -> 2327.8853 | J3: ='Free Cash Flow'!J17 -> 2375.5657
B5: Projection Year | F5: 1 | G5: 2 | H5: 3 | I5: 4 | J5: 5
B6: PV of Free Cash Flow | F6: =F3/(1+$C$11)^F5 -> 2121.672 | G6: =G3/(1+$C$11)^G5 -> 1981.6859 | H6: =H3/(1+$C$11)^H5 -> 1887.0049 | I6: =I3/(1+$C$11)^I5 -> 1800.3932 | J6: =J3/(1+$C$11)^J5 -> 1722.9563
B8: Implied Share Price Calculation | E8: Sensitivity Table:
B9: Sum of PV of FCF | C9: =SUM(F6:J6) -> 9513.7123
B10: Growth Rate | C10: 0.02 | G10: Growth Rate
B11: WACC | C11: =WACC!C17 -> 0.066347012 | F11: =C20 -> 5.19792 | G11: =H11-0.005 -> 0.01 | H11: =I11-0.005 -> 0.015 | I11: 0.02 | J11: =I11+0.005 -> 0.025 | K11: =J11+0.005 -> 0.03
B12: Terminal Value | C12: =(J3*(1+C10))/(C11-C10) -> 52281.192 | E12: WACC | F12: =F13-0.005 -> 0.056347012 | G12: 5.4507941 | H12: 6.1897034 | I12: 7.1319056 | J12: 8.3746794 | K12: 10.089148
B13: PV of Terminal Value | C13: =C12/(1+C11)^J5 -> 37918.635 | F13: =F14-0.005 -> 0.061347012 | G13: 4.7390302 | H13: 5.3229012 | I13: 6.0479845 | J13: 6.9725569 | K13: 8.1920769
B14: Enterprise Value | C14: =C13+C9 -> 47432.348 | F14: 0.066347012 | G14: 4.153617 | H14: 4.6249231 | I14: 5.19792 | J14: 5.9094993 | K14: 6.8168524
B15: (+) Cash | C15: ='Balance Sheet'!F25 -> 2255 | F15: =F14+0.005 -> 0.071347012 | G15: 3.6636595 | H15: 4.0508266 | I15: 4.5133958 | J15: 5.0757706 | K15: 5.7741587
B16: (-) Debt | C16: =WACC!C3 -> 14666 | F16: =F15+0.005 -> 0.076347012 | G16: 3.2475761 | H16: 3.570321 | I16: 3.950344 | J16: 4.4043777 | K16: 4.9563754
B17: (-) Minority Interest | C17: 4
B18: Equity Value | C18: =C14+C15-C16-C17 -> 35017.348
B19: Diluted Shares Outstanding | C19: 6736.8
B20: Implied Share Price | C20: =C18/C19 -> 5.19792

Sheet WACC
A1: Weighted Average Cost of Capital (WACC)
B2: Equity (£M) | C2: 25200
B3: Debt (£M) | C3: =SUM('Balance Sheet'!F31+'Balance Sheet'!F32+'Balance Sheet'!F43+'Balance Sheet'!F44)*-1 -> 14666
B5: Cost of Debt | C5: =('Income Statements'!E16/WACC!C3)*-1 -> 0.050865948
B6: Tax | C6: 0.269
B7: D/(D+E) | C7: =C3/(C2+C3) -> 0.36788241
B8: After Tax Cost of Debt | C8: =C5*(1-C6) -> 0.037183008
B10: Risk Free Rate | C10: 0.05197
B11: Expected Market Return | C11: =C10+C12 -> 0.10697
B12: Market Risk Premium | C12: 0.055
B13: Levered Beta | C13: 0.57
B14: E/(D+E) | C14: =C2/(C2+C3) -> 0.63211759
B15: Cost of Equity | C15: =C10+C13*(C12) -> 0.08332
B17: WACC | C17: =C8*C7+C15*C14 -> 0.066347012

Sheet Capital Expenditures
A1: Capital Expenditures
B2: Year | C2: 2023 | D2: 2024 | E2: 2025 | F2: 2026E | G2: 2027E | H2: 2028E | I2: 2029E | J2: 2030E
B3: Beginning PP&E | C3: ='Balance Sheet'!C4 -> 17060 | D3: ='Balance Sheet'!D4 -> 16862 | E3: ='Balance Sheet'!E4 -> 17221 | F3: =E6 -> 17262 | G3: =F6 -> 17331.423 | H3: =G6 -> 17401.125 | I3: =H6 -> 17471.108 | J3: =I6 -> 17541.372
B4: D&A | C4: ='Cash Flow Statement'!C5 -> 1700 | D4: ='Cash Flow Statement'!D5 -> 1723 | E4: ='Cash Flow Statement'!E5 -> 1775 | F4: =F10*F3 -> 1754.4093 | G4: =G10*G3 -> 1761.4651 | H4: =H10*H3 -> 1768.5492 | I4: =I10*I3 -> 1775.6618 | J4: =J10*J3 -> 1782.8031
B5: CapEx | C5: =C6-C3+C4 -> 1502 | D5: =D6-D3+D4 -> 2082 | E5: =E6-E3+E4 -> 1816 | F5: =F11*F3 -> 1823.8324 | G5: =G11*G3 -> 1831.1674 | H5: =H11*H3 -> 1838.5318 | I5: =I11*I3 -> 1845.9259 | J5: =J11*J3 -> 1853.3497
B6: Ending PP&E | C6: ='Balance Sheet'!D4 -> 16862 | D6: ='Balance Sheet'!E4 -> 17221 | E6: ='Balance Sheet'!F4 -> 17262 | F6: =F3-F4+F5 -> 17331.423 | G6: =G3-G4+G5 -> 17401.125 | H6: =H3-H4+H5 -> 17471.108 | I6: =I3-I4+I5 -> 17541.372 | J6: =J3-J4+J5 -> 17611.919
A8: Assumptions
B9: Year | C9: 2023 | D9: 2024 | E9: 2025 | F9: 2026E | G9: 2027E | H9: 2028E | I9: 2029E | J9: 2030E
B10: D&A as % of Beginning PP&E | C10: =C4/C3 -> 0.0996483 | D10: =D4/D3 -> 0.10218242 | E10: =E4/E3 -> 0.10307183 | F10: =AVERAGE(C10:E10) -> 0.10163418 | G10: =F10 -> 0.10163418 | H10: =F10 -> 0.10163418 | I10: =F10 -> 0.10163418 | J10: =F10 -> 0.10163418
B11: CapEx as % of Beginning PP&E | C11: =C5/C3 -> 0.088042204 | D11: =D5/D3 -> 0.1234729 | E11: =E5/E3 -> 0.10545265 | F11: =AVERAGE(C11:E11) -> 0.10565592 | G11: =F11 -> 0.10565592 | H11: =F11 -> 0.10565592 | I11: =F11 -> 0.10565592 | J11: =F11 -> 0.10565592

Sheet Net Working Capital
A1: Net Working Capital
B2: Year | C2: 2022 | D2: 2023 | E2: 2024 | F2: 2025 | G2: 2026E | H2: 2027E | I2: 2028E | J2: 2029E | K2: 2030E
B3: Inventories | C3: ='Balance Sheet'!C18 -> 2339 | D3: ='Balance Sheet'!D18 -> 2510 | E3: ='Balance Sheet'!E18 -> 2635 | F3: ='Balance Sheet'!F18 -> 2768 | G3: =-(G17*G14)/360 -> 2781.421 | H3: =-(H17*H14)/360 -> 2845.3936 | I3: =-(I17*I14)/360 -> 2905.1469 | J3: =-(J17*J14)/360 -> 2963.2498 | K3: =-(K17*K14)/360 -> 3022.5148
B4: Trade and Other Receivables | C4: ='Balance Sheet'!C19 -> 1263 | D4: ='Balance Sheet'!D19 -> 1315 | E4: ='Balance Sheet'!E19 -> 1349 | F4: ='Balance Sheet'!F19 -> 1210 | G4: =(G13*G16)/360 -> 1363.6843 | H4: =(H13*H16)/360 -> 1395.049 | I4: =(I13*I16)/360 -> 1424.3451 | J4: =(J13*J16)/360 -> 1452.832 | K4: =(K13*K16)/360 -> 1481.8886
B5: Current Assets | C5: =SUM(C3:C4) -> 3602 | D5: =SUM(D3:D4) -> 3825 | E5: =SUM(E3:E4) -> 3984 | F5: =SUM(F3:F4) -> 3978 | G5: =SUM(G3:G4) -> 4145.1052 | H5: =SUM(H3:H4) -> 4240.4427 | I5: =SUM(I3:I4) -> 4329.492 | J5: =SUM(J3:J4) -> 4416.0818 | K5: =SUM(K3:K4) -> 4504.4034
B7: Trade and Other Payables | C7: ='Balance Sheet'!C30 -> -9181 | D7: ='Balance Sheet'!D30 -> -9818 | E7: ='Balance Sheet'!E30 -> -10264 | F7: ='Balance Sheet'!F30 -> -10364 | G7: =(G18*G14)/360 -> -10704.658 | H7: =(H18*H14)/360 -> -10950.866 | I7: =(I18*I14)/360 -> -11180.834 | J7: =(J18*J14)/360 -> -11404.45 | K7: =(K18*K14)/360 -> -11632.539
B8: Provisions | C8: ='Balance Sheet'!C37 -> -283 | D8: ='Balance Sheet'!D37 -> -366 | E8: ='Balance Sheet'!E37 -> -306 | F8: ='Balance Sheet'!F37 -> -300 | G8: =G13*G20 -> -342.6501 | H8: =H13*H20 -> -350.53106 | I8: =I13*I20 -> -357.89221 | J8: =J13*J20 -> -365.05005 | K8: =K13*K20 -> -372.35105
B9: Current Liabilties | C9: =SUM(C7:C8) -> -9464 | D9: =SUM(D7:D8) -> -10184 | E9: =SUM(E7:E8) -> -10570 | F9: =SUM(F7:F8) -> -10664 | G9: =SUM(G7:G8) -> -11047.308 | H9: =SUM(H7:H8) -> -11301.397 | I9: =SUM(I7:I8) -> -11538.726 | J9: =SUM(J7:J8) -> -11769.5 | K9: =SUM(K7:K8) -> -12004.89
A11: Assumptions
B12: Year | C12: 2022 | D12: 2023 | E12: 2024 | F12: 2025 | G12: 2026E | H12: 2027E | I12: 2028E | J12: 2029E | K12: 2030E
B13: Revenue | D13: ='Free Cash Flow'!C3 -> 65762 | E13: ='Free Cash Flow'!D3 -> 68187 | F13: ='Free Cash Flow'!E3 -> 69916 | G13: ='Free Cash Flow'!F3 -> 71663.9 | H13: ='Free Cash Flow'!G3 -> 73312.17 | I13: ='Free Cash Flow'!H3 -> 74851.725 | J13: ='Free Cash Flow'!I3 -> 76348.76 | K13: ='Free Cash Flow'!J3 -> 77875.735
B14: COGS | D14: ='Free Cash Flow'!C4 -> -62034 | E14: ='Free Cash Flow'!D4 -> -62836 | F14: ='Free Cash Flow'!E4 -> -64205 | G14: ='Free Cash Flow'!F4 -> -66483.833 | H14: ='Free Cash Flow'!G4 -> -68012.961 | I14: ='Free Cash Flow'!H4 -> -69441.234 | J14: ='Free Cash Flow'!I4 -> -70830.058 | K14: ='Free Cash Flow'!J4 -> -72246.659
B16: Days Sales Outstanding (DSO) | D16: =(D4/D13)*360 -> 7.1986862 | E16: =(E4/E13)*360 -> 7.1221787 | F16: =(F4/F13)*360 -> 6.2303335 | G16: =AVERAGE(D16:F16) -> 6.8503995 | H16: =G16 -> 6.8503995 | I16: =G16 -> 6.8503995 | J16: =G16 -> 6.8503995 | K16: =G16 -> 6.8503995
B17: Days Inventory Outstanding (DIO) | D17: =(D3/-D14)*360 -> 14.566206 | E17: =(E3/-E14)*360 -> 15.096442 | F17: =(F3/-F14)*360 -> 15.520287 | G17: =AVERAGE(D17:F17) -> 15.060978 | H17: =$G17 -> 15.060978 | I17: =$G17 -> 15.060978 | J17: =$G17 -> 15.060978 | K17: =$G17 -> 15.060978
B18: Days Payable Outstanding (DPO) | D18: =(D7/D14)*360 -> 56.976497 | E18: =(E7/E14)*360 -> 58.804507 | F18: =(F7/F14)*360 -> 58.111362 | G18: =AVERAGE(D18:F18) -> 57.964122 | H18: =$G18 -> 57.964122 | I18: =$G18 -> 57.964122 | J18: =$G18 -> 57.964122 | K18: =$G18 -> 57.964122
B20: Provisions as a % of Revenue | D20: =D8/D13 -> -0.0055655242 | E20: =E8/E13 -> -0.0044876589 | F20: =F8/F13 -> -0.0042908633 | G20: =AVERAGE(D20:F20) -> -0.0047813488 | H20: =$G20 -> -0.0047813488 | I20: =$G20 -> -0.0047813488 | J20: =$G20 -> -0.0047813488 | K20: =$G20 -> -0.0047813488

Sheet Historical Data ->

Sheet Income Statements
A1: Group Income Statements: | C1: 44958 | D1: 45323 | E1: 45689
C2: £M | D2: £M | E2: £M
B3: Continuing operations
B4: Revenue from sale of goods and services | D4: 67673 | E4: 69191
B5: Insurance revenue | D5: 514 | E5: 725
B6: Revenue | C6: 65762 | D6: 68187 | E6: 69916
B7: Cost of sales | C7: -62034 | D7: -62836 | E7: -64205
B8: Insurance service expenses | D8: -454 | E8: -598
B9: Net expenses from reinsurance contracts held | D9: -48 | E9: -62
B10: Impairment (loss)/reversal on financial assets | C10: -67
B11: Gross profit/(loss) | C11: 3661 | D11: 4849 | E11: 5051
B12: Administrative expenses | C12: -2136 | D12: -2028 | E12: -2340
B13: Operating profit/(loss) | C13: 1525 | D13: 2821 | E13: 2711
B14: Share of post-tax profit/(loss) of joint ventures and associates | C14: 8 | D14: 6 | E14: -4
B15: Finance income | C15: 85 | D15: 267 | E15: 254
B16: Finance costs | C16: -618 | D16: -805 | E16: -746
B17: Profit/(loss) before tax from continuing operations | C17: 1000 | D17: 2289 | E17: 2215
B18: Taxation | C18: -247 | D18: -525 | E18: -611
B19: Profit/(loss) for the year from continuing operations | C19: 753 | D19: 1764 | E19: 1604
B20: Discontinued operations
B21: Profit/(loss) for the year from discontinued operations | C21: -9 | D21: -572 | E21: 26
B22: Profit/(loss) for the year | C22: 744 | D22: 1192 | E22: 1630
B23: Attributable to:
B24: Owners of the parent | C24: 745 | D24: 1188 | E24: 1626
B25: Non-controlling interests | C25: -1 | D25: 4 | E25: 4
B26: Earnings per share from continuing and discontinued operations
B27: Basic | C27: 10.05p | D27: 16.74p | E27: 23.79p
B28: Diluted | C28: 9.96p | D28: 16.56p | E28: 23.51p
B29: Earnings per share from continuing operations
B30: Basic | C30: 10.17p | D30: 24.80p | E30: 23.41p
B31: Diluted | C31: 10.08p | D31: 24.53p | E31: 32.13p

Sheet Balance Sheet
A1: Group Balance Sheet: | C1: 44593 | D1: 44958 | E1: 45323 | F1: 45689
B2: Non-current assets
B3: Goodwil and other intangible assets | C3: 5360 | D3: 5375 | E3: 5066 | F3: 5087
B4: Property, plant and equipmennt | C4: 17060 | D4: 16862 | E4: 17221 | F4: 17262
B5: Right of use assets | C5: 5720 | D5: 5500 | E5: 5478 | F5: 5569
B6: Investment property | C6: 22 | D6: 24 | E6: 24 | F6: 24
B7: Investments in joint ventures and associates | C7: 86 | D7: 93 | E7: 102 | F7: 110
B8: Other investments | C8: 1253 | D8: 1339 | E8: 1546 | F8: 934
B9: Trade and other receivables | C9: 159 | D9: 79 | E9: 36 | F9: 158
B10: Loans and advances to customers | C10: 3141 | D10: 3029 | E10: - | F10: -
B11: Reinsurance assets | C11: 184 | D11: 145 | E11: 125 | F11: 124
B12: Derivative financial instruments | C12: 942 | D12: 873 | E12: 781 | F12: 663
B13: Post-emolpyment benefit surplus | C13: 3150 | D13: 6 | E13: 22 | F13: 56
B14: Deferred tax assets | C14: 85 | D14: 82 | E14: 32 | F14: 47
C15: =SUM(C3:C14) -> 37162 | D15: 33407 | E15: 30433 | F15: 30034
B16: Current assets
B17: Other investments | C17: 226 | D17: 353 | E17: 206 | F17: 151
B18: Inventories | C18: 2339 | D18: 2510 | E18: 2635 | F18: 2768
B19: Trade and other receivables | C19: 1263 | D19: 1315 | E19: 1349 | F19: 1210
B20: Loans and advances to customers | C20: 3349 | D20: 4052 | E20: - | F20: -
B21: Reinsurance assets | C21: 61 | D21: 72 | E21: - | F21: -
B22: Derivative financial instruments | C22: 69 | D22: 57 | E22: 55 | F22: 172
B23: Current tax assets | C23: 93 | D23: 63 | E23: 110 | F23: 27
B24: Short-term investments | C24: 2076 | D24: 1628 | E24: 2128 | F24: 2223
B25: Cash and cash equivalents | C25: 2345 | D25: 2465 | E25: 2340 | F25: 2255
C26: =SUM(C17:C25) -> 11821 | D26: 12515 | E26: 8823 | F26: 8806
B27: Assets of the disposal and non-current assets classified as held for sale | C27: 368 | D27: 210 | E27: 7783 | F27: 50
C28: =SUM(C26:C27) -> 12189 | D28: 12725 | E28: 16606 | F28: 8856
B29: Current liabilties
B30: Trade and other payables | C30: -9181 | D30: -9818 | E30: -10264 | F30: -10364
B31: Borrowings | C31: -725 | D31: -1770 | E31: -1536 | F31: -1861
B32: Lease Liabilties | C32: -547 | D32: -595 | E32: -584 | F32: -618
B33: Insurance Contract provisions | C33: -623 | D33: -570 | E33: -526 | F33: -652
B34: Customer depositis and deposits from banks | C34: -4729 | D34: -4485 | E34: -108 | F34: -
B35: Derivative financial instruments | C35: -26 | D35: -99 | E35: -25 | F35: -12
B36: Current tax liabilities | C36: -11 | D36: -18 | E36: -1 | F36: -13
B37: Provisions | C37: -283 | D37: -366 | E37: -306 | F37: -300
C38: -16125 | D38: -17721 | E38: -13350 | F38: -13820
B39: Liabilities of the disposal group classified as held for sale | C39: -14 | D39: -14 | E39: -7122 | F39: -
B40: Net current liabilities | C40: -3950 | D40: -5010 | E40: -3866 | F40: -4964
...

Sheet Cash Flow Statement
A1: Group Cash Flow Statement: | C1: 44958 | D1: 45323 | E1: 45689
B2: Cash flows generated from/(used in) operating activties
B3: Operating profit/(loss) of continuing operations | C3: 1525 | D3: 2821 | E3: 2711
B4: Operating profit/(loss) of discontinued operations | C4: -9 | D4: -659 | E4: 35
B5: Depreciation and amortisation | C5: 1700 | D5: 1723 | E5: 1775
B6: (Profit)/loss arising on sale of property, plant and equipment, investment property, intangible assets, assets classified as held for sale and early termination of leases | C6: -76 | D6: -53 | E6: 1
B7: (Profit)/loss arising from sale of other investments | C7: 3 | D7: - | E7: -
B8: (profit)/loss arising on sale of joint ventures and associates | C8: - | D8: -9 | E8: -
B9: (Profit)/loss arising on sale of subsidiares | C9: - | D9: -12 | E9: -
B10: Net impairment loss on property, plant and equipment, right of use assets, intangible assets and investment property | C10: 982 | D10: -28 | E10: 298
B11: Impairment loss on other investments | C11: - | D11: - | E11: 10
B12: Net remeasurement loss on non-current assets held for sale | C12: 23 | D12: 720 | E12: 64
B13: Adjustment for non-cash element of pensions charge | C13: - | D13: - | E13: -
B14: Other defined benefit pension scheme payments | C14: -23 | D14: -29 | E14: -30
B15: Share-based payments | C15: 59 | D15: 78 | E15: 37
B16: Tesco Bank fair value movements included in operating profit/(loss) | C16: 70 | D16: 71 | E16: 9
B17: Retail (increase)/decrease in inventories | C17: -147 | D17: -150 | E17: 141
B18: Retail (increase)/decrease in trade and other receivables | C18: -54 | D18: -118 | E18: -5
B19: Retail increase/(decrease) in trade and other payables | C19: 643 | D19: 714 | E19: 158
B20: Retail increase/(decrease) in provsions | C20: 75 | D20: -72 | E20: -10
B21: Retail (increase)/decrease in working capital | C21: 517 | D21: 374
B22: Tesco Bank (increase)/decrease in loans and advances to customers | C22: -696 | D22: -714
B23: Tesco Bank (increase) /decrease in trade, reinsurance and other receivables | C23: -60 | D23: -9
B24: Tesco Bank increase/(decrease) in customer and bank deposits, trade, insurance and other payables | C24: 369 | D24: 584
B25: Tesco Bank increase/(decrease) in provsions | C25: -7 | D25: 28
B26: Tesco Bank (increase)/decrease in working capital | C26: -274 | D26: -111
B27: Cash generated from/(used in) operations | C27: 4497 | D27: 4886 | E27: 4057
B28: Interest paid | C28: -652 | D28: -824 | E28: -769
B29: Corporation tax paid | C29: -123 | D29: -223 | E29: -366
B30: Net cash generated from (used in) operating activities | C30: 3722 | D30: 3839 | E30: 2922
B31: Cash flows generated from/(used in) investing activities
B32: Proceeds from sale of property, plant and equipment, investment property, intangible assets and assets classified as held for sale | C32: 342 | D32: 55 | E32: 137
B33: Purchase of property, plant and equipment, investment property and other long-term assets | C33: -971 | D33: -1108 | E33: -1247
B34: Purchase of intangible assets | C34: -279 | D34: -278 | E34: -292
B35: Disposal of subsidiaries, net of cash disposed | C35: - | D35: 15 | E35: -
B36: Disposal of banking operations, net of cash disposed | C36: - | D36: - | E36: 157
B37: Acquistion of subsidiries net of cash acquired | C37: -71 | D37: -17 | E37: -46
B38: Proceeds from sale of joint ventures and assocaites | C38: - | D38: 9 | E38: -
B39: Increase in loans to joint ventures and associates | C39: -1 | D39: -61 | E39: -1
B40: Investment in joint ventures and associates | C40: -10 | D40: -9 | E40: -15
...
